<?xml version="1.0" encoding="utf-8"?>
<mujoco>
	<compiler angle="radian" coordinate="local" meshdir="../stls/fetch" texturedir="../textures"></compiler>
	<option timestep="0.002">
		<flag warmstart="enable"></flag>
	</option>
	<size njmax="1000"/>

	<include file="shared_250.xml"></include>
	
	<worldbody>
		<geom name="floor0" pos="0.8 0.75 0" size="0.85 0.7 1" type="plane" condim="3" material="floor_mat"></geom>
		<body name="floor0" pos="0.8 0.75 0">
			<site name="target0" pos="0 0 0.5" size="0.02 0.02 0.02" rgba="1 0 0 0.1" type="sphere"></site>
		</body>

		<include file="robot_250.xml"></include>
		
		<body pos="1.3 0.75 0.2" name="table0">
			<geom size="0.25 0.35 0.2" name="table0" type="box" mass="2000" material="table_mat"></geom>
			<site pos="0 0 0.2" size="0.23 0.33 0.005" type="box" name="table0:surface_site" group="3"/>
		</body>
		
		<body name="object0" pos="0.025 0.025 0.025">
			<joint name="object0:joint1" type="slide" axis="1 0 0" damping="0.01"></joint>
			<joint name="object0:joint2" type="slide" axis="0 1 0" damping="0.01"></joint>
			<joint name="object0:joint3" type="slide" axis="0 0 1" damping="0.01"></joint>
			<geom pos="0 0 -0.025" size="0.03 0.03 0.005" type="box" condim="6" name="object0_wall1" material="block_mat" mass="0.05"></geom>
			<geom pos="0 0 0.025" size="0.03 0.03 0.005" type="box" condim="6" name="object0_wall2" material="block_mat" mass="0.05"></geom>
			<geom pos="0 0.025 0" size="0.03 0.005 0.03" type="box" condim="6" name="object0_wall3" material="block_mat" mass="0.05"></geom>
			<geom pos="0 -0.025 0" size="0.03 0.005 0.03" type="box" condim="6" name="object0_wall4" material="block_mat" mass="0.05"></geom>
			<site name="spring_end1" pos="0 -0.02 0" size="0.001" rgba="1 0 0 1"/>
			<site name="spring_end2" pos="0 0.02 0" size="0.001" rgba="1 0 0 1"/>
			<body name="object1" pos="0 0 0">
    			<geom pos="0 0 0" size="0.005" type="sphere" condim="3" name="object1" rgba="1 1 0 1" mass="1"></geom>
    			<joint name="object1:joint" type="slide" axis="0 1 0" damping="1e1"></joint>
    			<site name="object1" pos="0 0 0" size="0.001" rgba="1 0 0 0"/>
    		</body>
			<site name="object0" pos="0 0 0" size="0.01" rgba="1 0 0 1" type="sphere" group="3"></site>
			<site name="object0:surface_site" pos="0 0 0.0" size="0.026 0.026 0.020" rgba="1 0 0 1" type="box" group="4"></site>
		</body>

		<light directional="true" ambient="0.2 0.2 0.2" diffuse="0.8 0.8 0.8" specular="0.3 0.3 0.3" castshadow="false" pos="0 0 4" dir="0 0 -1" name="light0"></light>
	</worldbody>
    <tendon>
        <spatial range="0 0.04" stiffness="5e1" limited="true">
            <site site="spring_end1"/>
            <site site="object1"/>
        </spatial>
        <spatial range="0 0.04" stiffness="5e1" limited="true">
            <site site="spring_end2"/>
            <site site="object1"/>
        </spatial>
    </tendon>
    <contact>
        <pair geom1="object0_wall1" geom2="robot0:r_gripper_finger_link" condim="6"/>
        <pair geom1="object0_wall1" geom2="robot0:l_gripper_finger_link" condim="6"/>
        <pair geom1="object0_wall2" geom2="robot0:r_gripper_finger_link" condim="6"/>
        <pair geom1="object0_wall2" geom2="robot0:l_gripper_finger_link" condim="6"/>
        <pair geom1="object0_wall3" geom2="robot0:r_gripper_finger_link" condim="6"/>
        <pair geom1="object0_wall3" geom2="robot0:l_gripper_finger_link" condim="6"/>
        <pair geom1="object0_wall4" geom2="robot0:r_gripper_finger_link" condim="6"/>
        <pair geom1="object0_wall4" geom2="robot0:l_gripper_finger_link" condim="6"/>
    </contact>
	<actuator>
		<position ctrllimited="true" ctrlrange="-1.0 1.0" joint="robot0:l_gripper_finger_joint" kp="30000" name="robot0:l_gripper_finger_joint" user="1"></position>
		<position ctrllimited="true" ctrlrange="-1.0 1.0" joint="robot0:r_gripper_finger_joint" kp="30000" name="robot0:r_gripper_finger_joint" user="1"></position>
	</actuator>
	<sensor>
    	<actuatorvel actuator="robot0:l_gripper_finger_joint" name="robot0:l_actuator_vel"/>
    	<actuatorvel actuator="robot0:r_gripper_finger_joint" name="robot0:r_actuator_vel"/>
    	<jointpos name="contents_pos" joint="object1:joint"/>
	</sensor>
</mujoco>
